<?xml version='1.0'?>
<sdf version='1.4'>
    <model name="auto robot">
        <static>false</static>
        <link name="center">
            <pose>0 0 0 1.5707 0 0</pose>
            <collision name="collision">
                <geometry>
                    <mesh>
                        <uri>model://AutoRobotPrototype/meshes/STL/touch_model.stl</uri>
                    </mesh>
                </geometry>
            </collision>
            <visual name="visual">
                <geometry>
                    <mesh>
                        <uri>model://AutoRobotPrototype/meshes/dae/center_part.dae</uri>
                    </mesh>
                </geometry>
            </visual>
            <inertial>
                <mass>8</mass> 
                <!--<inertia> ixx="0.01" ixy="0.0" ixz="0.0" iyy="0.01" iyz="0.0" izz="0.5"</inertia>--> 
                <pose>0.3 0.16 0.41 0 0 0</pose>
            </inertial>
        </link>
        <!--leg-->
        <link name="steer_roll_0">
            <pose>0.2 -0.2 .115 0 0 0</pose>
            <collision name="collision">
                <geometry>
                    <mesh>
                        <uri>model://AutoRobotPrototype/meshes/STL/steer_roll.STL</uri>
                    </mesh>
                </geometry>
            </collision>
            <visual name="visual">
                <geometry>
                    <mesh>
                        <uri>model://AutoRobotPrototype/meshes/dae/steer_roll.dae</uri>
                    </mesh>
                </geometry>
            </visual>
            <inertial>
                <mass>1</mass> 
                <!--<inertia> ixx="0.01" ixy="0.0" ixz="0.0" iyy="0.01" iyz="0.0" izz="0.5"</inertia>--> 
                <pose>-0.06 0.025 0 0 0 0</pose>
            </inertial>
        </link>
        <link name="steer_roll_1">
            <pose>0.18 -.68 .115 0 0 0</pose>
            <collision name="collision">
                <geometry>
                    <mesh>
                        <uri>model://AutoRobotPrototype/meshes/STL/steer_roll.STL</uri>
                    </mesh>
                </geometry>
            </collision>
            <visual name="visual">
                <geometry>
                    <mesh>
                        <uri>model://AutoRobotPrototype/meshes/dae/steer_roll.dae</uri>
                    </mesh>
                </geometry>
            </visual>
            <inertial>
                <mass>1</mass> 
                <!--<inertia> ixx="0.01" ixy="0.0" ixz="0.0" iyy="0.01" iyz="0.0" izz="0.5"</inertia>--> 
                <pose>-0.06 0.025 0 0 0 0</pose>
            </inertial>
        </link>
        <link name="steer_roll_2">
            <pose>0.58 -0.44 .115 0 0 0</pose>
            <collision name="collision">
                <geometry>
                    <mesh>
                        <uri>model://AutoRobotPrototype/meshes/STL/steer_roll.STL</uri>
                    </mesh>
                </geometry>
            </collision>
            <visual name="visual">
                <geometry>
                    <mesh>
                        <uri>model://AutoRobotPrototype/meshes/dae/steer_roll.dae</uri>
                    </mesh>
                </geometry>
            </visual>
            <inertial>
                <mass>1</mass> 
                <!--<inertia> ixx="0.01" ixy="0.0" ixz="0.0" iyy="0.01" iyz="0.0" izz="0.5"</inertia>--> 
                <pose>-0.06 0.025 0 0 0 0</pose>
            </inertial>
        </link>
        <link name="red_in_0">
            <pose>0.178145 -0.203764 0.017723 0 -0 1.5707</pose>
            <collision name="collision">
                <geometry>
                    <mesh>
                        <uri>model://AutoRobotPrototype/meshes/STL/red_in.STL</uri>
                    </mesh>
                </geometry>
            </collision>
            <visual name="visual">
                <geometry>
                    <mesh>
                        <uri>model://AutoRobotPrototype/meshes/dae/red_in.dae</uri>
                    </mesh>
                </geometry>
            </visual>
            <inertial>
                <mass>1</mass> 
                <!--<inertia> ixx="0.01" ixy="0.0" ixz="0.0" iyy="0.01" iyz="0.0" izz="0.5"</inertia>--> 
                <pose>0.03 0.035 0.035 0 0 0</pose>
            </inertial>
        </link>
        <link name="red_in_1">
            <pose>0.159887 -0.687 0.017816 0 -0 1.5707</pose>
            <collision name="collision">
                <geometry>
                    <mesh>
                        <uri>model://AutoRobotPrototype/meshes/STL/red_in.STL</uri>
                    </mesh>
                </geometry>
            </collision>
            <visual name="visual">
                <geometry>
                    <mesh>
                        <uri>model://AutoRobotPrototype/meshes/dae/red_in.dae</uri>
                    </mesh>
                </geometry>
            </visual>
            <inertial>
                <mass>1</mass> 
                <!--<inertia> ixx="0.01" ixy="0.0" ixz="0.0" iyy="0.01" iyz="0.0" izz="0.5"</inertia>--> 
                <pose>0.03 0.035 0.035 0 0 0</pose>
            </inertial>
        </link>
        <link name="red_in_2">
            <pose>0.559502 -0.447 0.019141 0 -0 1.5707</pose>
            <collision name="collision">
                <geometry>
                    <mesh>
                        <uri>model://AutoRobotPrototype/meshes/STL/red_in.STL</uri>
                    </mesh>
                </geometry>
            </collision>
            <visual name="visual">
                <geometry>
                    <mesh>
                        <uri>model://AutoRobotPrototype/meshes/dae/red_in.dae</uri>
                    </mesh>
                </geometry>
            </visual>
            <inertial>
                <mass>1</mass> 
                <!--<inertia> ixx="0.01" ixy="0.0" ixz="0.0" iyy="0.01" iyz="0.0" izz="0.5"</inertia>--> 
                <pose>0.03 0.035 0.035 0 0 0</pose>
            </inertial>
        </link>
        <joint type='revolute' name='roll_0'>
            <pose>-0.058 0.026 0 0 0 0</pose>
            <child>steer_roll_0</child>
            <parent>center</parent>
            <axis>
                <xyz>0 0 1</xyz>
            </axis>
        </joint>
        <joint type='revolute' name='roll_1'>
            <pose>-0.058 0.026 0 0 0 0</pose>
            <child>steer_roll_1</child>
            <parent>center</parent>
            <axis>
                <xyz>0 0 1</xyz>
            </axis>
        </joint>
        <joint type='revolute' name='roll_2'>
            <pose>-0.058 0.026 0 0 0 0</pose>
            <child>steer_roll_2</child>
            <parent>center</parent>
            <axis>
                <xyz>0 0 1</xyz>
            </axis>
        </joint>
        <joint type='revolute' name='red_0'>
            <pose>0. 0.035 0.035 0 0 0</pose>
            <child>red_in_0</child>
            <parent>steer_roll_0</parent>
            <axis>
                <xyz>0 1 0</xyz>
            </axis>
        </joint>
        <joint type='revolute' name='red_1'>
            <pose>0. 0.035 0.035 0 0 0</pose>
            <child>red_in_1</child>
            <parent>steer_roll_1</parent>
            <axis>
                <xyz>0 1 0</xyz>
            </axis>
        </joint>
        <joint type='revolute' name='red_2'>
            <pose>0. 0.035 0.035 0 0 0</pose>
            <child>red_in_2</child>
            <parent>steer_roll_2</parent>
            <axis>
                <xyz>0 1 0</xyz>
            </axis>
        </joint>
        <!--arm-->
        <link name="root">
            <pose>0 0.0495 0.012 1.5707 0 -0.02</pose>
            <collision name="collision">
                <geometry>
                    <mesh>
                        <uri>model://AutoRobotPrototype/meshes/STL/arm_root.STL</uri>
                    </mesh>
                </geometry>
            </collision>
            <visual name="visual">
                <geometry>
                    <mesh>
                        <uri>model://AutoRobotPrototype/meshes/dae/arm_root.dae</uri>
                    </mesh>
                </geometry>
            </visual>
            <inertial>
                <mass>2</mass>
                <!--<inertia> ixx="0.01" ixy="0.0" ixz="0.0" iyy="0.01" iyz="0.0" izz="0.5"</inertia>-->
                <pose>0.23 0.28 0.465 0 0 0</pose>
            </inertial>
        </link>
        <joint name="arm_shifter" type="prismatic">
            <pose>0 0 0 0 0 -0.02</pose>
            <child>root</child>
            <parent>center</parent>
            <axis>
                <limit>
                    <lower>-0.1</lower>
                    <upper>0.2</upper>
                </limit>
                <xyz>1 0 0</xyz>
            </axis>
        </joint>
        <link name="second_arm">
            <pose>0.21 0.045 0.85 -1.5707 1 3.1415</pose>
            <collision name="collision">
                <geometry>
                    <mesh>
                        <uri>model://AutoRobotPrototype/meshes/STL/arm_second.STL</uri>
                    </mesh>
                </geometry>
            </collision>
            <visual name="visual">
                <geometry>
                    <mesh>
                        <uri>model://AutoRobotPrototype/meshes/dae/arm_second.dae</uri>
                    </mesh>
                </geometry>
            </visual>
            <inertial>
                <mass>0.7</mass>
                <!--<inertia> ixx="0.01" ixy="0.0" ixz="0.0" iyy="0.01" iyz="0.0" izz="0.5"</inertia>-->
                <pose>0.2 0.4 0.465 0 0 0</pose>
            </inertial>
        </link>
        <joint type='revolute' name='root_second'>
            <pose>0.45 0.297 0.3 0 0 0</pose>
            <child>second_arm</child>
            <parent>root</parent>
            <axis>
                <limit>
                    <lower>-2.7</lower>
                    <upper>0.8</upper>
                    <!--<upper>0</upper>-->
                </limit>
                <xyz>0 1 0</xyz>
            </axis>
        </joint>
        <!--koga arm-->
        <link name="arm_lock">
            <pose>0.53 -0.545 0.745 0 2 0</pose>
            <collision name="collision">
                <geometry>
                    <mesh>
                        <uri>model://AutoRobotPrototype/meshes/STL/arm_lock.STL</uri>
                    </mesh>
                </geometry>
            </collision>
            <visual name="visual">
                <geometry>
                    <mesh>
                        <uri>model://AutoRobotPrototype/meshes/dae/arm_lock.dae</uri>
                    </mesh>
                </geometry>
            </visual>
            <inertial>
                <mass>0.5</mass>
                <!--<inertia> ixx="0.01" ixy="0.0" ixz="0.0" iyy="0.01" iyz="0.0" izz="0.5"</inertia>-->
                <pose>0.13 0.13 0.26 0 0 0</pose>
            </inertial>
        </link>
        <joint type='revolute' name='second_lock'>
            <pose>0.13 0 0.13 0 0 0</pose>
            <child>arm_lock</child>
            <parent>second_arm</parent>
            <axis>
                <limit>
                    <lower>-3.4</lower>
                    <upper>1.3</upper>
                </limit>
                <xyz>0 1 0</xyz>
            </axis>
        </joint>

        <link name="arm_roll">
            <pose>0.53 -0.545 0.745 0 2 0</pose>
            <collision name="collision">
                <geometry>
                    <mesh>
                        <uri>model://AutoRobotPrototype/meshes/STL/arm_roll.STL</uri>
                    </mesh>
                </geometry>
            </collision>
            <visual name="visual">
                <geometry>
                    <mesh>
                        <uri>model://AutoRobotPrototype/meshes/dae/arm_roll.dae</uri>
                    </mesh>
                </geometry>
            </visual>
            <inertial>
                <mass>0.1</mass>
                <!--<inertia> ixx="0.01" ixy="0.0" ixz="0.0" iyy="0.01" iyz="0.0" izz="0.5"</inertia>-->
                <pose>0.13 0.13 0.301 0 0 0</pose>
            </inertial>
        </link>
        
        <joint type='revolute' name='lock_roll'>
            <pose>0.128 0.127 0.1 0 0 0</pose>
            <child>arm_roll</child>
            <parent>arm_lock</parent>
            <axis>
                <upper>1.5707</upper>
                <lower>-1.5707</lower>
                <xyz>1 0 -0.45</xyz>
            </axis>
        </joint>

        <link name="arm_connecter1">
            <pose>0.53 -0.545 0.745 0 2 0</pose>
            <collision name="collision">
                <geometry>
                    <mesh>
                        <uri>model://AutoRobotPrototype/meshes/STL/arm_connecter1.STL</uri>
                    </mesh>
                </geometry>
            </collision>
            <visual name="visual">
                <geometry>
                    <mesh>
                        <uri>model://AutoRobotPrototype/meshes/dae/arm_connecter1.dae</uri>
                    </mesh>
                </geometry>
            </visual>
            <inertial>
                <mass>0.001</mass>
                <!--<inertia> ixx="0.01" ixy="0.0" ixz="0.0" iyy="0.01" iyz="0.0" izz="0.5"</inertia>-->
                <pose>0.173 0.083 0.304 0 0 0</pose>
            </inertial>
        </link>
        
        <link name="arm_connecter2">
            <pose>0.53 -0.545 0.745 0 2 0</pose>
            <collision name="collision">
                <geometry>
                    <mesh>
                        <uri>model://AutoRobotPrototype/meshes/STL/arm_connecter2.STL</uri>
                    </mesh>
                </geometry>
            </collision>
            <visual name="visual">
                <geometry>
                    <mesh>
                        <uri>model://AutoRobotPrototype/meshes/dae/arm_connecter2.dae</uri>
                    </mesh>
                </geometry>
            </visual>
            <inertial>
                <mass>0.001</mass>
                <!--<inertia> ixx="0.01" ixy="0.0" ixz="0.0" iyy="0.01" iyz="0.0" izz="0.5"</inertia>-->
                <pose>0.171 0.17 0.304 0 0 0</pose>
            </inertial>
        </link>

        <link name="arm_connecter3">
            <pose>0.53 -0.545 0.745 0 2 0</pose>
            <collision name="collision">
                <geometry>
                    <mesh>
                        <uri>model://AutoRobotPrototype/meshes/STL/arm_connecter3.STL</uri>
                    </mesh>
                </geometry>
            </collision>
            <visual name="visual">
                <geometry>
                    <mesh>
                        <uri>model://AutoRobotPrototype/meshes/dae/arm_connecter3.dae</uri>
                    </mesh>
                </geometry>
            </visual>
            <inertial>
                <mass>0.001</mass>
                <!--<inertia> ixx="0.01" ixy="0.0" ixz="0.0" iyy="0.01" iyz="0.0" izz="0.5"</inertia>-->
                <pose>0.082 0.172 0.3035 0 0 0</pose>
            </inertial>
        </link>

        <link name="arm_connecter4">
            <pose>0.53 -0.545 0.745 0 2 0</pose>
            <collision name="collision">
                <geometry>
                    <mesh>
                        <uri>model://AutoRobotPrototype/meshes/STL/arm_connecter4.STL</uri>
                    </mesh>
                </geometry>
            </collision>
            <visual name="visual">
                <geometry>
                    <mesh>
                        <uri>model://AutoRobotPrototype/meshes/dae/arm_connecter4.dae</uri>
                    </mesh>
                </geometry>
            </visual>
            <inertial>
                <mass>0.001</mass>
                <!--<inertia> ixx="0.01" ixy="0.0" ixz="0.0" iyy="0.01" iyz="0.0" izz="0.5"</inertia>-->
                <pose>0.084 0.082 0.3035 0 0 0</pose>
            </inertial>
        </link>

        <joint type='revolute' name='roll_co1'>
            <pose>0.16 0.095 0.25 0 0 0</pose>
            <child>arm_connecter1</child>
            <parent>arm_roll</parent>
            <axis>
                <xyz>1 0 -0.45</xyz>
            </axis>
        </joint>

        <joint type='revolute' name='roll_co2'>
            <pose>0.16 0.16 0.25 0 0 0</pose>
            <child>arm_connecter2</child>
            <parent>arm_roll</parent>
            <axis>
                <xyz>1 0 -0.45</xyz>
            </axis>
        </joint>

        <joint type='revolute' name='roll_co3'>
            <pose>0.095 0.16 0.25 0 0 0</pose>
            <child>arm_connecter3</child>
            <parent>arm_roll</parent>
            <axis>
                <xyz>1 0 -0.45</xyz>
            </axis>
        </joint>

        <joint type='revolute' name='roll_co4'>
            <pose>0.097 0.095 0.25 0 0 0</pose>
            <child>arm_connecter4</child>
            <parent>arm_roll</parent>
            <axis>
                <xyz>1 0 -0.45</xyz>
            </axis>
        </joint>

        <link name="arm_l1">
            <pose>0.53 -0.545 0.745 0 2 0</pose>
            <collision name="collision">
                <geometry>
                    <mesh>
                        <uri>model://AutoRobotPrototype/meshes/STL/arm_l1.STL</uri>
                    </mesh>
                </geometry>
            </collision>
            <visual name="visual">
                <geometry>
                    <mesh>
                        <uri>model://AutoRobotPrototype/meshes/dae/arm_l1.dae</uri>
                    </mesh>
                </geometry>
            </visual>
            <inertial>
                <mass>0.01</mass>
                <!--<inertia> ixx="0.01" ixy="0.0" ixz="0.0" iyy="0.01" iyz="0.0" izz="0.5"</inertia>-->
                <pose>0.21 0.21 0.34 0 0 0</pose>
            </inertial>
        </link>

        <link name="arm_l2">
            <pose>0.53 -0.545 0.745 0 2 0</pose>
            <collision name="collision">
                <geometry>
                    <mesh>
                        <uri>model://AutoRobotPrototype/meshes/STL/arm_l2.STL</uri>
                    </mesh>
                </geometry>
            </collision>
            <visual name="visual">
                <geometry>
                    <mesh>
                        <uri>model://AutoRobotPrototype/meshes/dae/arm_l2.dae</uri>
                    </mesh>
                </geometry>
            </visual>
            <inertial>
                <mass>0.01</mass>
                <!--<inertia> ixx="0.01" ixy="0.0" ixz="0.0" iyy="0.01" iyz="0.0" izz="0.5"</inertia>-->
                <pose>0.0445 0.0445 0.34 0 0 0</pose>
            </inertial>
        </link>

        <joint type='revolute' name='co2_l1'>
            <pose>0.184 0.184 0.25 0 0 0</pose>
            <child>arm_l1</child>
            <parent>arm_connecter2</parent>
            <axis>
                <xyz>1 0 -0.45</xyz>
            </axis>
        </joint>

        <joint type='revolute' name='co4_l2'>
            <pose>0.073 0.071 0.25 0 0 0</pose>
            <child>arm_l2</child>
            <parent>arm_connecter4</parent>
            <axis>
                <xyz>1 0 -0.45</xyz>
            </axis>
        </joint>

        <link name="arm_s1">
            <pose>0.53 -0.545 0.745 0 2 0</pose>
            <collision name="collision">
                <geometry>
                    <mesh>
                        <uri>model://AutoRobotPrototype/meshes/STL/arm_s1.STL</uri>
                    </mesh>
                </geometry>
            </collision>
            <visual name="visual">
                <geometry>
                    <mesh>
                        <uri>model://AutoRobotPrototype/meshes/dae/arm_s1.dae</uri>
                    </mesh>
                </geometry>
            </visual>
            <inertial>
                <mass>0.01</mass>
                <!--<inertia> ixx="0.01" ixy="0.0" ixz="0.0" iyy="0.01" iyz="0.0" izz="0.5"</inertia>-->
                <pose>0.21 0.0445 0.33 0 0 0</pose>
            </inertial>
        </link>

        <link name="arm_s2">
            <pose>0.53 -0.545 0.745 0 2 0</pose>
            <collision name="collision">
                <geometry>
                    <mesh>
                        <uri>model://AutoRobotPrototype/meshes/STL/arm_s2.STL</uri>
                    </mesh>
                </geometry>
            </collision>
            <visual name="visual">
                <geometry>
                    <mesh>
                        <uri>model://AutoRobotPrototype/meshes/dae/arm_s2.dae</uri>
                    </mesh>
                </geometry>
            </visual>
            <inertial>
                <mass>0.01</mass>
                <!--<inertia> ixx="0.01" ixy="0.0" ixz="0.0" iyy="0.01" iyz="0.0" izz="0.5"</inertia>-->
                <pose>0.0445 0.21 0.33 0 0 0</pose>
            </inertial>
        </link>

        <joint type='revolute' name='co1_s1'>
            <pose>0.184 0.071 0.25 0 0 0</pose>
            <child>arm_s1</child>
            <parent>arm_connecter1</parent>
            <axis>
                <xyz>1 0 -0.45</xyz>
            </axis>
        </joint>

        <joint type='revolute' name='co3_s2'>
            <pose>0.073 0.184 0.25 0 0 0</pose>
            <child>arm_s2</child>
            <parent>arm_connecter3</parent>
            <axis>
                <xyz>1 0 -0.45</xyz>
            </axis>
        </joint>

        <joint type='prismatic' name='lock_l1'>
            <pose>0.16 0.16 0.35 0 0 0</pose>
            <child>arm_l1</child>
            <parent>arm_lock</parent>
            <axis>
                <xyz>-0.451 1.115 -1.01</xyz>
                <limit>
                    <lower>-0.035</lower>
                    <upper>0</upper>
                </limit>
            </axis>
        </joint>

        <joint type='prismatic' name='lock_l2'>
            <pose>0.095 0.095 0.35 0 0 0</pose>
            <child>arm_l2</child>
            <parent>arm_lock</parent>
            <axis>
                <xyz>0.451 -1.115 1.01</xyz>
                <limit>
                    <lower>-0.035</lower>
                    <upper>0</upper>
                </limit>
            </axis>
        </joint>

        <joint type='prismatic' name='lock_s1'>
            <pose>0.16 0.095 0.35 0 0 0</pose>
            <child>arm_s1</child>
            <parent>arm_lock</parent>
            <axis>
                <xyz>-0.451 -1.115 -1.01</xyz>
                <limit>
                    <lower>-0.035</lower>
                    <upper>0</upper>
                </limit>
            </axis>
        </joint>

        <joint type='prismatic' name='lock_s2'>
            <pose>0.095 0.16 0.35 0 0 0</pose>
            <child>arm_s2</child>
            <parent>arm_lock</parent>
            <axis>
                <xyz>0.451 1.115 1.01</xyz>
                <limit>
                    <lower>-0.035</lower>
                    <upper>0</upper>
                </limit>
            </axis>
        </joint>

        <plugin name="mono_motor_plugin" filename="libmono_motor_plugin.so">
            <ros>
                <namespace></namespace>
            </ros>
            <motor_joint>red_0</motor_joint>
            <name>red</name>
            <max_rpm>100</max_rpm>
            <radius>10</radius>
        </plugin>
    </model>
</sdf>